Workbook

Sheet 01 Synthetic Records
A1: Document ID | B1: Verified Expected Pages | C1: Received Pages | D1: Page Count Match | E1: Ground Truth Complete | F1: Defect Type | G1: Baseline Detected | H1: Control Detected | I1: Baseline Escaped | J1: Control Escaped | K1: Baseline Rework Min | L1: Control Rework Min | M1: Baseline Status | N1: Control Status | O1: Verification Source | P1: Content Check
A2: SYN-0001 | B2: 5 | C2: 5 | D2: =IF(B2=C2,"MATCH","MISMATCH") -> MATCH | E2: =IF(F2="None",1,0) -> 1 | F2: None | G2: 0 | H2: 0 | I2: =IF(AND(E2=0,G2=0),1,0) -> 0 | J2: =IF(AND(E2=0,H2=0),1,0) -> 0 | K2: =I2*'05 Methodology'!$B$7 -> 0 | L2: =J2*'05 Methodology'!$B$7 -> 0 | M2: =IF(G2=1,"FLAG / HOLD","INDEXED") -> INDEXED | N2: =IF(H2=1,"FLAG / HOLD","INDEXED") -> INDEXED | O2: Synthetic manifest + checklist | P2: Verified
A3: SYN-0002 | B3: 6 | C3: 6 | D3: =IF(B3=C3,"MATCH","MISMATCH") -> MATCH | E3: =IF(F3="None",1,0) -> 1 | F3: None | G3: 0 | H3: 0 | I3: =IF(AND(E3=0,G3=0),1,0) -> 0 | J3: =IF(AND(E3=0,H3=0),1,0) -> 0 | K3: =I3*'05 Methodology'!$B$7 -> 0 | L3: =J3*'05 Methodology'!$B$7 -> 0 | M3: =IF(G3=1,"FLAG / HOLD","INDEXED") -> INDEXED | N3: =IF(H3=1,"FLAG / HOLD","INDEXED") -> INDEXED | O3: Synthetic manifest + checklist | P3: Verified
A4: SYN-0003 | B4: 7 | C4: 7 | D4: =IF(B4=C4,"MATCH","MISMATCH") -> MATCH | E4: =IF(F4="None",1,0) -> 1 | F4: None | G4: 0 | H4: 0 | I4: =IF(AND(E4=0,G4=0),1,0) -> 0 | J4: =IF(AND(E4=0,H4=0),1,0) -> 0 | K4: =I4*'05 Methodology'!$B$7 -> 0 | L4: =J4*'05 Methodology'!$B$7 -> 0 | M4: =IF(G4=1,"FLAG / HOLD","INDEXED") -> INDEXED | N4: =IF(H4=1,"FLAG / HOLD","INDEXED") -> INDEXED | O4: Synthetic manifest + checklist | P4: Verified
A5: SYN-0004 | B5: 8 | C5: 8 | D5: =IF(B5=C5,"MATCH","MISMATCH") -> MATCH | E5: =IF(F5="None",1,0) -> 1 | F5: None | G5: 0 | H5: 0 | I5: =IF(AND(E5=0,G5=0),1,0) -> 0 | J5: =IF(AND(E5=0,H5=0),1,0) -> 0 | K5: =I5*'05 Methodology'!$B$7 -> 0 | L5: =J5*'05 Methodology'!$B$7 -> 0 | M5: =IF(G5=1,"FLAG / HOLD","INDEXED") -> INDEXED | N5: =IF(H5=1,"FLAG / HOLD","INDEXED") -> INDEXED | O5: Synthetic manifest + checklist | P5: Verified
A6: SYN-0005 | B6: 4 | C6: 4 | D6: =IF(B6=C6,"MATCH","MISMATCH") -> MATCH | E6: =IF(F6="None",1,0) -> 0 | F6: Content missing / wrong page | G6: 1 | H6: 1 | I6: =IF(AND(E6=0,G6=0),1,0) -> 0 | J6: =IF(AND(E6=0,H6=0),1,0) -> 0 | K6: =I6*'05 Methodology'!$B$7 -> 0 | L6: =J6*'05 Methodology'!$B$7 -> 0 | M6: =IF(G6=1,"FLAG / HOLD","INDEXED") -> FLAG / HOLD | N6: =IF(H6=1,"FLAG / HOLD","INDEXED") -> FLAG / HOLD | O6: Synthetic manifest + checklist | P6: Mismatch
A7: SYN-0006 | B7: 5 | C7: 5 | D7: =IF(B7=C7,"MATCH","MISMATCH") -> MATCH | E7: =IF(F7="None",1,0) -> 1 | F7: None | G7: 0 | H7: 0 | I7: =IF(AND(E7=0,G7=0),1,0) -> 0 | J7: =IF(AND(E7=0,H7=0),1,0) -> 0 | K7: =I7*'05 Methodology'!$B$7 -> 0 | L7: =J7*'05 Methodology'!$B$7 -> 0 | M7: =IF(G7=1,"FLAG / HOLD","INDEXED") -> INDEXED | N7: =IF(H7=1,"FLAG / HOLD","INDEXED") -> INDEXED | O7: Synthetic manifest + checklist | P7: Verified
A8: SYN-0007 | B8: 6 | C8: 6 | D8: =IF(B8=C8,"MATCH","MISMATCH") -> MATCH | E8: =IF(F8="None",1,0) -> 1 | F8: None | G8: 0 | H8: 0 | I8: =IF(AND(E8=0,G8=0),1,0) -> 0 | J8: =IF(AND(E8=0,H8=0),1,0) -> 0 | K8: =I8*'05 Methodology'!$B$7 -> 0 | L8: =J8*'05 Methodology'!$B$7 -> 0 | M8: =IF(G8=1,"FLAG / HOLD","INDEXED") -> INDEXED | N8: =IF(H8=1,"FLAG / HOLD","INDEXED") -> INDEXED | O8: Synthetic manifest + checklist | P8: Verified
A9: SYN-0008 | B9: 7 | C9: 7 | D9: =IF(B9=C9,"MATCH","MISMATCH") -> MATCH | E9: =IF(F9="None",1,0) -> 1 | F9: None | G9: 0 | H9: 0 | I9: =IF(AND(E9=0,G9=0),1,0) -> 0 | J9: =IF(AND(E9=0,H9=0),1,0) -> 0 | K9: =I9*'05 Methodology'!$B$7 -> 0 | L9: =J9*'05 Methodology'!$B$7 -> 0 | M9: =IF(G9=1,"FLAG / HOLD","INDEXED") -> INDEXED | N9: =IF(H9=1,"FLAG / HOLD","INDEXED") -> INDEXED | O9: Synthetic manifest + checklist | P9: Verified
A10: SYN-0009 | B10: 8 | C10: 8 | D10: =IF(B10=C10,"MATCH","MISMATCH") -> MATCH | E10: =IF(F10="None",1,0) -> 1 | F10: None | G10: 0 | H10: 0 | I10: =IF(AND(E10=0,G10=0),1,0) -> 0 | J10: =IF(AND(E10=0,H10=0),1,0) -> 0 | K10: =I10*'05 Methodology'!$B$7 -> 0 | L10: =J10*'05 Methodology'!$B$7 -> 0 | M10: =IF(G10=1,"FLAG / HOLD","INDEXED") -> INDEXED | N10: =IF(H10=1,"FLAG / HOLD","INDEXED") -> INDEXED | O10: Synthetic manifest + checklist | P10: Verified
A11: SYN-0010 | B11: 4 | C11: 4 | D11: =IF(B11=C11,"MATCH","MISMATCH") -> MATCH | E11: =IF(F11="None",1,0) -> 0 | F11: Content missing / wrong page | G11: 1 | H11: 1 | I11: =IF(AND(E11=0,G11=0),1,0) -> 0 | J11: =IF(AND(E11=0,H11=0),1,0) -> 0 | K11: =I11*'05 Methodology'!$B$7 -> 0 | L11: =J11*'05 Methodology'!$B$7 -> 0 | M11: =IF(G11=1,"FLAG / HOLD","INDEXED") -> FLAG / HOLD | N11: =IF(H11=1,"FLAG / HOLD","INDEXED") -> FLAG / HOLD | O11: Synthetic manifest + checklist | P11: Mismatch
A12: SYN-0011 | B12: 5 | C12: 5 | D12: =IF(B12=C12,"MATCH","MISMATCH") -> MATCH | E12: =IF(F12="None",1,0) -> 1 | F12: None | G12: 0 | H12: 0 | I12: =IF(AND(E12=0,G12=0),1,0) -> 0 | J12: =IF(AND(E12=0,H12=0),1,0) -> 0 | K12: =I12*'05 Methodology'!$B$7 -> 0 | L12: =J12*'05 Methodology'!$B$7 -> 0 | M12: =IF(G12=1,"FLAG / HOLD","INDEXED") -> INDEXED | N12: =IF(H12=1,"FLAG / HOLD","INDEXED") -> INDEXED | O12: Synthetic manifest + checklist | P12: Verified
A13: SYN-0012 | B13: 6 | C13: 6 | D13: =IF(B13=C13,"MATCH","MISMATCH") -> MATCH | E13: =IF(F13="None",1,0) -> 1 | F13: None | G13: 0 | H13: 0 | I13: =IF(AND(E13=0,G13=0),1,0) -> 0 | J13: =IF(AND(E13=0,H13=0),1,0) -> 0 | K13: =I13*'05 Methodology'!$B$7 -> 0 | L13: =J13*'05 Methodology'!$B$7 -> 0 | M13: =IF(G13=1,"FLAG / HOLD","INDEXED") -> INDEXED | N13: =IF(H13=1,"FLAG / HOLD","INDEXED") -> INDEXED | O13: Synthetic manifest + checklist | P13: Verified
... A501: SYN-0500 | B501: 4 | C501: 4 | D501: =IF(B501=C501,"MATCH","MISMATCH") -> MATCH | E501: =IF(F501="None",1,0) -> 1 | F501: None | G501: 0 | H501: 0 | I501: =IF(AND(E501=0,G501=0),1,0) -> 0 | J501: =IF(AND(E501=0,H501=0),1,0) -> 0 | K501: =I501*'05 Methodology'!$B$7 -> 0 | L501: =J501*'05 Methodology'!$B$7 -> 0 | M501: =IF(G501=1,"FLAG / HOLD","INDEXED") -> INDEXED | N501: =IF(H501=1,"FLAG / HOLD","INDEXED") -> INDEXED | O501: Synthetic manifest + checklist | P501: Verified

Sheet 02 KPI Dashboard
A1: CASE STUDY 01 | DOCUMENT COMPLETENESS
A3: Measure | B3: Baseline | C3: Proposed Control | D3: Validation
A4: Documents | B4: =COUNTA('01 Synthetic Records'!A2:A501) -> 500 | C4: =B4 -> 500 | D4: =IF(AND(ABS(B4-500)<0.00001,ABS(C4-500)<0.00001),"PASS","FAIL") -> PASS
A5: Incomplete documents | B5: =COUNTIF('01 Synthetic Records'!E2:E501,0) -> 40 | C5: =B5 -> 40 | D5: =IF(AND(ABS(B5-40)<0.00001,ABS(C5-40)<0.00001),"PASS","FAIL") -> PASS
A6: Detected defects | B6: =SUM('01 Synthetic Records'!G2:G501) -> 25 | C6: =SUM('01 Synthetic Records'!H2:H501) -> 38 | D6: =IF(AND(ABS(B6-25)<0.00001,ABS(C6-38)<0.00001),"PASS","FAIL") -> PASS
A7: Escaped defects | B7: =SUM('01 Synthetic Records'!I2:I501) -> 15 | C7: =SUM('01 Synthetic Records'!J2:J501) -> 2 | D7: =IF(AND(ABS(B7-15)<0.00001,ABS(C7-2)<0.00001),"PASS","FAIL") -> PASS
A8: Detection rate | B8: =IFERROR(B6/B5,0) -> 0.625 | C8: =IFERROR(C6/C5,0) -> 0.95 | D8: =IF(AND(ABS(B8-0.625)<0.00001,ABS(C8-0.95)<0.00001),"PASS","FAIL") -> PASS
A9: Escape rate | B9: =IFERROR(B7/B5,0) -> 0.375 | C9: =IFERROR(C7/C5,0) -> 0.05 | D9: =IF(AND(ABS(B9-0.375)<0.00001,ABS(C9-0.05)<0.00001),"PASS","FAIL") -> PASS
A10: Escaped rework hours | B10: =SUM('01 Synthetic Records'!K2:K501)/60 -> 5 | C10: =SUM('01 Synthetic Records'!L2:L501)/60 -> 0.66666667 | D10: =IF(AND(ABS(B10-5)<0.00001,ABS(C10-0.666666666666666)<0.00001),"PASS","FAIL") -> PASS
A11: Defect rate | B11: =IFERROR(B5/B4,0) -> 0.08 | C11: =IFERROR(C5/C4,0) -> 0.08 | D11: =IF(AND(B6+B7=B5,C6+C7=C5),"PASS","FAIL") -> PASS
A12: First-pass completeness | B12: =1-B11 -> 0.92 | C12: =1-C11 -> 0.92 | D12: =IF(AND(B11=C11,B12=C12),"PASS","FAIL") -> PASS
A13: Avoided downstream hours | B13: =B10-C10 -> 4.3333333 | C13: =B10-C10 -> 4.3333333
A16: INTERPRETATION | B16: Paired synthetic counterfactual; not measured effectiveness
A17: CAUTION | B17: Avoided downstream rework is not net labor savings

Sheet 03 Exception Log
A1: Document ID | B1: Defect Type | C1: Expected | D1: Received | E1: Baseline Detected | F1: Control Detected | G1: Baseline Escaped | H1: Control Escaped | I1: Baseline Rework Min | J1: Control Rework Min
A2: ='01 Synthetic Records'!A6 -> SYN-0005 | B2: ='01 Synthetic Records'!F6 -> Content missing / wrong page | C2: ='01 Synthetic Records'!B6 -> 4 | D2: ='01 Synthetic Records'!C6 -> 4 | E2: ='01 Synthetic Records'!G6 -> 1 | F2: ='01 Synthetic Records'!H6 -> 1 | G2: ='01 Synthetic Records'!I6 -> 0 | H2: ='01 Synthetic Records'!J6 -> 0 | I2: ='01 Synthetic Records'!K6 -> 0 | J2: ='01 Synthetic Records'!L6 -> 0
A3: ='01 Synthetic Records'!A11 -> SYN-0010 | B3: ='01 Synthetic Records'!F11 -> Content missing / wrong page | C3: ='01 Synthetic Records'!B11 -> 4 | D3: ='01 Synthetic Records'!C11 -> 4 | E3: ='01 Synthetic Records'!G11 -> 1 | F3: ='01 Synthetic Records'!H11 -> 1 | G3: ='01 Synthetic Records'!I11 -> 0 | H3: ='01 Synthetic Records'!J11 -> 0 | I3: ='01 Synthetic Records'!K11 -> 0 | J3: ='01 Synthetic Records'!L11 -> 0
A4: ='01 Synthetic Records'!A18 -> SYN-0017 | B4: ='01 Synthetic Records'!F18 -> Missing page | C4: ='01 Synthetic Records'!B18 -> 6 | D4: ='01 Synthetic Records'!C18 -> 5 | E4: ='01 Synthetic Records'!G18 -> 0 | F4: ='01 Synthetic Records'!H18 -> 1 | G4: ='01 Synthetic Records'!I18 -> 1 | H4: ='01 Synthetic Records'!J18 -> 0 | I4: ='01 Synthetic Records'!K18 -> 20 | J4: ='01 Synthetic Records'!L18 -> 0
A5: ='01 Synthetic Records'!A32 -> SYN-0031 | B5: ='01 Synthetic Records'!F32 -> Missing page | C5: ='01 Synthetic Records'!B32 -> 5 | D5: ='01 Synthetic Records'!C32 -> 4 | E5: ='01 Synthetic Records'!G32 -> 0 | F5: ='01 Synthetic Records'!H32 -> 1 | G5: ='01 Synthetic Records'!I32 -> 1 | H5: ='01 Synthetic Records'!J32 -> 0 | I5: ='01 Synthetic Records'!K32 -> 20 | J5: ='01 Synthetic Records'!L32 -> 0
A6: ='01 Synthetic Records'!A63 -> SYN-0062 | B6: ='01 Synthetic Records'!F63 -> Missing page | C6: ='01 Synthetic Records'!B63 -> 6 | D6: ='01 Synthetic Records'!C63 -> 5 | E6: ='01 Synthetic Records'!G63 -> 1 | F6: ='01 Synthetic Records'!H63 -> 1 | G6: ='01 Synthetic Records'!I63 -> 0 | H6: ='01 Synthetic Records'!J63 -> 0 | I6: ='01 Synthetic Records'!K63 -> 0 | J6: ='01 Synthetic Records'!L63 -> 0
A7: ='01 Synthetic Records'!A78 -> SYN-0077 | B7: ='01 Synthetic Records'!F78 -> Missing page | C7: ='01 Synthetic Records'!B78 -> 6 | D7: ='01 Synthetic Records'!C78 -> 5 | E7: ='01 Synthetic Records'!G78 -> 1 | F7: ='01 Synthetic Records'!H78 -> 1 | G7: ='01 Synthetic Records'!I78 -> 0 | H7: ='01 Synthetic Records'!J78 -> 0 | I7: ='01 Synthetic Records'!K78 -> 0 | J7: ='01 Synthetic Records'!L78 -> 0
A8: ='01 Synthetic Records'!A81 -> SYN-0080 | B8: ='01 Synthetic Records'!F81 -> Content missing / wrong page | C8: ='01 Synthetic Records'!B81 -> 4 | D8: ='01 Synthetic Records'!C81 -> 4 | E8: ='01 Synthetic Records'!G81 -> 1 | F8: ='01 Synthetic Records'!H81 -> 1 | G8: ='01 Synthetic Records'!I81 -> 0 | H8: ='01 Synthetic Records'!J81 -> 0 | I8: ='01 Synthetic Records'!K81 -> 0 | J8: ='01 Synthetic Records'!L81 -> 0
A9: ='01 Synthetic Records'!A87 -> SYN-0086 | B9: ='01 Synthetic Records'!F87 -> Missing page | C9: ='01 Synthetic Records'!B87 -> 5 | D9: ='01 Synthetic Records'!C87 -> 4 | E9: ='01 Synthetic Records'!G87 -> 1 | F9: ='01 Synthetic Records'!H87 -> 1 | G9: ='01 Synthetic Records'!I87 -> 0 | H9: ='01 Synthetic Records'!J87 -> 0 | I9: ='01 Synthetic Records'!K87 -> 0 | J9: ='01 Synthetic Records'!L87 -> 0
A10: ='01 Synthetic Records'!A120 -> SYN-0119 | B10: ='01 Synthetic Records'!F120 -> Missing page | C10: ='01 Synthetic Records'!B120 -> 6 | D10: ='01 Synthetic Records'!C120 -> 5 | E10: ='01 Synthetic Records'!G120 -> 1 | F10: ='01 Synthetic Records'!H120 -> 1 | G10: ='01 Synthetic Records'!I120 -> 0 | H10: ='01 Synthetic Records'!J120 -> 0 | I10: ='01 Synthetic Records'!K120 -> 0 | J10: ='01 Synthetic Records'!L120 -> 0
A11: ='01 Synthetic Records'!A129 -> SYN-0128 | B11: ='01 Synthetic Records'!F129 -> Missing page | C11: ='01 Synthetic Records'!B129 -> 7 | D11: ='01 Synthetic Records'!C129 -> 6 | E11: ='01 Synthetic Records'!G129 -> 1 | F11: ='01 Synthetic Records'!H129 -> 1 | G11: ='01 Synthetic Records'!I129 -> 0 | H11: ='01 Synthetic Records'!J129 -> 0 | I11: ='01 Synthetic Records'!K129 -> 0 | J11: ='01 Synthetic Records'!L129 -> 0
A12: ='01 Synthetic Records'!A133 -> SYN-0132 | B12: ='01 Synthetic Records'!F133 -> Missing page | C12: ='01 Synthetic Records'!B133 -> 6 | D12: ='01 Synthetic Records'!C133 -> 5 | E12: ='01 Synthetic Records'!G133 -> 1 | F12: ='01 Synthetic Records'!H133 -> 1 | G12: ='01 Synthetic Records'!I133 -> 0 | H12: ='01 Synthetic Records'!J133 -> 0 | I12: ='01 Synthetic Records'!K133 -> 0 | J12: ='01 Synthetic Records'!L133 -> 0
A13: ='01 Synthetic Records'!A143 -> SYN-0142 | B13: ='01 Synthetic Records'!F143 -> Missing page | C13: ='01 Synthetic Records'!B143 -> 6 | D13: ='01 Synthetic Records'!C143 -> 5 | E13: ='01 Synthetic Records'!G143 -> 0 | F13: ='01 Synthetic Records'!H143 -> 1 | G13: ='01 Synthetic Records'!I143 -> 1 | H13: ='01 Synthetic Records'!J143 -> 0 | I13: ='01 Synthetic Records'!K143 -> 20 | J13: ='01 Synthetic Records'!L143 -> 0
A14: ='01 Synthetic Records'!A147 -> SYN-0146 | B14: ='01 Synthetic Records'!F147 -> Missing page | C14: ='01 Synthetic Records'!B147 -> 5 | D14: ='01 Synthetic Records'!C147 -> 4 | E14: ='01 Synthetic Records'!G147 -> 0 | F14: ='01 Synthetic Records'!H147 -> 1 | G14: ='01 Synthetic Records'!I147 -> 1 | H14: ='01 Synthetic Records'!J147 -> 0 | I14: ='01 Synthetic Records'!K147 -> 20 | J14: ='01 Synthetic Records'!L147 -> 0
A15: ='01 Synthetic Records'!A165 -> SYN-0164 | B15: ='01 Synthetic Records'!F165 -> Missing page | C15: ='01 Synthetic Records'!B165 -> 8 | D15: ='01 Synthetic Records'!C165 -> 7 | E15: ='01 Synthetic Records'!G165 -> 1 | F15: ='01 Synthetic Records'!H165 -> 1 | G15: ='01 Synthetic Records'!I165 -> 0 | H15: ='01 Synthetic Records'!J165 -> 0 | I15: ='01 Synthetic Records'!K165 -> 0 | J15: ='01 Synthetic Records'!L165 -> 0
A16: ='01 Synthetic Records'!A172 -> SYN-0171 | B16: ='01 Synthetic Records'!F172 -> Missing page | C16: ='01 Synthetic Records'!B172 -> 5 | D16: ='01 Synthetic Records'!C172 -> 4 | E16: ='01 Synthetic Records'!G172 -> 0 | F16: ='01 Synthetic Records'!H172 -> 0 | G16: ='01 Synthetic Records'!I172 -> 1 | H16: ='01 Synthetic Records'!J172 -> 1 | I16: ='01 Synthetic Records'!K172 -> 20 | J16: ='01 Synthetic Records'!L172 -> 20
A17: ='01 Synthetic Records'!A197 -> SYN-0196 | B17: ='01 Synthetic Records'!F197 -> Missing page | C17: ='01 Synthetic Records'!B197 -> 6 | D17: ='01 Synthetic Records'!C197 -> 5 | E17: ='01 Synthetic Records'!G197 -> 0 | F17: ='01 Synthetic Records'!H197 -> 1 | G17: ='01 Synthetic Records'!I197 -> 1 | H17: ='01 Synthetic Records'!J197 -> 0 | I17: ='01 Synthetic Records'!K197 -> 20 | J17: ='01 Synthetic Records'!L197 -> 0
A18: ='01 Synthetic Records'!A198 -> SYN-0197 | B18: ='01 Synthetic Records'!F198 -> Missing page | C18: ='01 Synthetic Records'!B198 -> 6 | D18: ='01 Synthetic Records'!C198 -> 5 | E18: ='01 Synthetic Records'!G198 -> 0 | F18: ='01 Synthetic Records'!H198 -> 1 | G18: ='01 Synthetic Records'!I198 -> 1 | H18: ='01 Synthetic Records'!J198 -> 0 | I18: ='01 Synthetic Records'!K198 -> 20 | J18: ='01 Synthetic Records'!L198 -> 0
A19: ='01 Synthetic Records'!A199 -> SYN-0198 | B19: ='01 Synthetic Records'!F199 -> Missing page | C19: ='01 Synthetic Records'!B199 -> 7 | D19: ='01 Synthetic Records'!C199 -> 6 | E19: ='01 Synthetic Records'!G199 -> 0 | F19: ='01 Synthetic Records'!H199 -> 1 | G19: ='01 Synthetic Records'!I199 -> 1 | H19: ='01 Synthetic Records'!J199 -> 0 | I19: ='01 Synthetic Records'!K199 -> 20 | J19: ='01 Synthetic Records'!L199 -> 0
A20: ='01 Synthetic Records'!A223 -> SYN-0222 | B20: ='01 Synthetic Records'!F223 -> Missing page | C20: ='01 Synthetic Records'!B223 -> 6 | D20: ='01 Synthetic Records'!C223 -> 5 | E20: ='01 Synthetic Records'!G223 -> 1 | F20: ='01 Synthetic Records'!H223 -> 1 | G20: ='01 Synthetic Records'!I223 -> 0 | H20: ='01 Synthetic Records'!J223 -> 0 | I20: ='01 Synthetic Records'!K223 -> 0 | J20: ='01 Synthetic Records'!L223 -> 0
A21: ='01 Synthetic Records'!A226 -> SYN-0225 | B21: ='01 Synthetic Records'!F226 -> Content missing / wrong page | C21: ='01 Synthetic Records'!B226 -> 4 | D21: ='01 Synthetic Records'!C226 -> 4 | E21: ='01 Synthetic Records'!G226 -> 1 | F21: ='01 Synthetic Records'!H226 -> 1 | G21: ='01 Synthetic Records'!I226 -> 0 | H21: ='01 Synthetic Records'!J226 -> 0 | I21: ='01 Synthetic Records'!K226 -> 0 | J21: ='01 Synthetic Records'!L226 -> 0
A22: ='01 Synthetic Records'!A285 -> SYN-0284 | B22: ='01 Synthetic Records'!F285 -> Missing page | C22: ='01 Synthetic Records'!B285 -> 8 | D22: ='01 Synthetic Records'!C285 -> 7 | E22: ='01 Synthetic Records'!G285 -> 0 | F22: ='01 Synthetic Records'!H285 -> 1 | G22: ='01 Synthetic Records'!I285 -> 1 | H22: ='01 Synthetic Records'!J285 -> 0 | I22: ='01 Synthetic Records'!K285 -> 20 | J22: ='01 Synthetic Records'!L285 -> 0
A23: ='01 Synthetic Records'!A297 -> SYN-0296 | B23: ='01 Synthetic Records'!F297 -> Missing page | C23: ='01 Synthetic Records'!B297 -> 5 | D23: ='01 Synthetic Records'!C297 -> 4 | E23: ='01 Synthetic Records'!G297 -> 0 | F23: ='01 Synthetic Records'!H297 -> 1 | G23: ='01 Synthetic Records'!I297 -> 1 | H23: ='01 Synthetic Records'!J297 -> 0 | I23: ='01 Synthetic Records'!K297 -> 20 | J23: ='01 Synthetic Records'!L297 -> 0
A24: ='01 Synthetic Records'!A300 -> SYN-0299 | B24: ='01 Synthetic Records'!F300 -> Missing page | C24: ='01 Synthetic Records'!B300 -> 8 | D24: ='01 Synthetic Records'!C300 -> 7 | E24: ='01 Synthetic Records'!G300 -> 1 | F24: ='01 Synthetic Records'!H300 -> 1 | G24: ='01 Synthetic Records'!I300 -> 0 | H24: ='01 Synthetic Records'!J300 -> 0 | I24: ='01 Synthetic Records'!K300 -> 0 | J24: ='01 Synthetic Records'!L300 -> 0
A25: ='01 Synthetic Records'!A302 -> SYN-0301 | B25: ='01 Synthetic Records'!F302 -> Missing page | C25: ='01 Synthetic Records'!B302 -> 6 | D25: ='01 Synthetic Records'!C302 -> 5 | E25: ='01 Synthetic Records'!G302 -> 1 | F25: ='01 Synthetic Records'!H302 -> 1 | G25: ='01 Synthetic Records'!I302 -> 0 | H25: ='01 Synthetic Records'!J302 -> 0 | I25: ='01 Synthetic Records'!K302 -> 0 | J25: ='01 Synthetic Records'!L302 -> 0
A26: ='01 Synthetic Records'!A319 -> SYN-0318 | B26: ='01 Synthetic Records'!F319 -> Missing page | C26: ='01 Synthetic Records'!B319 -> 7 | D26: ='01 Synthetic Records'!C319 -> 6 | E26: ='01 Synthetic Records'!G319 -> 0 | F26: ='01 Synthetic Records'!H319 -> 1 | G26: ='01 Synthetic Records'!I319 -> 1 | H26: ='01 Synthetic Records'!J319 -> 0 | I26: ='01 Synthetic Records'!K319 -> 20 | J26: ='01 Synthetic Records'!L319 -> 0
A27: ='01 Synthetic Records'!A337 -> SYN-0336 | B27: ='01 Synthetic Records'!F337 -> Missing page | C27: ='01 Synthetic Records'!B337 -> 6 | D27: ='01 Synthetic Records'!C337 -> 5 | E27: ='01 Synthetic Records'!G337 -> 0 | F27: ='01 Synthetic Records'!H337 -> 1 | G27: ='01 Synthetic Records'!I337 -> 1 | H27: ='01 Synthetic Records'!J337 -> 0 | I27: ='01 Synthetic Records'!K337 -> 20 | J27: ='01 Synthetic Records'!L337 -> 0
A28: ='01 Synthetic Records'!A340 -> SYN-0339 | B28: ='01 Synthetic Records'!F340 -> Missing page | C28: ='01 Synthetic Records'!B340 -> 8 | D28: ='01 Synthetic Records'!C340 -> 7 | E28: ='01 Synthetic Records'!G340 -> 1 | F28: ='01 Synthetic Records'!H340 -> 1 | G28: ='01 Synthetic Records'!I340 -> 0 | H28: ='01 Synthetic Records'!J340 -> 0 | I28: ='01 Synthetic Records'!K340 -> 0 | J28: ='01 Synthetic Records'!L340 -> 0
A29: ='01 Synthetic Records'!A355 -> SYN-0354 | B29: ='01 Synthetic Records'!F355 -> Missing page | C29: ='01 Synthetic Records'!B355 -> 8 | D29: ='01 Synthetic Records'!C355 -> 7 | E29: ='01 Synthetic Records'!G355 -> 1 | F29: ='01 Synthetic Records'!H355 -> 1 | G29: ='01 Synthetic Records'!I355 -> 0 | H29: ='01 Synthetic Records'!J355 -> 0 | I29: ='01 Synthetic Records'!K355 -> 0 | J29: ='01 Synthetic Records'!L355 -> 0
A30: ='01 Synthetic Records'!A372 -> SYN-0371 | B30: ='01 Synthetic Records'!F372 -> Missing page | C30: ='01 Synthetic Records'!B372 -> 6 | D30: ='01 Synthetic Records'!C372 -> 5 | E30: ='01 Synthetic Records'!G372 -> 1 | F30: ='01 Synthetic Records'!H372 -> 1 | G30: ='01 Synthetic Records'!I372 -> 0 | H30: ='01 Synthetic Records'!J372 -> 0 | I30: ='01 Synthetic Records'!K372 -> 0 | J30: ='01 Synthetic Records'!L372 -> 0
A31: ='01 Synthetic Records'!A376 -> SYN-0375 | B31: ='01 Synthetic Records'!F376 -> Content missing / wrong page | C31: ='01 Synthetic Records'!B376 -> 4 | D31: ='01 Synthetic Records'!C376 -> 4 | E31: ='01 Synthetic Records'!G376 -> 1 | F31: ='01 Synthetic Records'!H376 -> 1 | G31: ='01 Synthetic Records'!I376 -> 0 | H31: ='01 Synthetic Records'!J376 -> 0 | I31: ='01 Synthetic Records'!K376 -> 0 | J31: ='01 Synthetic Records'!L376 -> 0
A32: ='01 Synthetic Records'!A392 -> SYN-0391 | B32: ='01 Synthetic Records'!F392 -> Missing page | C32: ='01 Synthetic Records'!B392 -> 5 | D32: ='01 Synthetic Records'!C392 -> 4 | E32: ='01 Synthetic Records'!G392 -> 1 | F32: ='01 Synthetic Records'!H392 -> 1 | G32: ='01 Synthetic Records'!I392 -> 0 | H32: ='01 Synthetic Records'!J392 -> 0 | I32: ='01 Synthetic Records'!K392 -> 0 | J32: ='01 Synthetic Records'!L392 -> 0
A33: ='01 Synthetic Records'!A401 -> SYN-0400 | B33: ='01 Synthetic Records'!F401 -> Content missing / wrong page | C33: ='01 Synthetic Records'!B401 -> 4 | D33: ='01 Synthetic Records'!C401 -> 4 | E33: ='01 Synthetic Records'!G401 -> 0 | F33: ='01 Synthetic Records'!H401 -> 1 | G33: ='01 Synthetic Records'!I401 -> 1 | H33: ='01 Synthetic Records'!J401 -> 0 | I33: ='01 Synthetic Records'!K401 -> 20 | J33: ='01 Synthetic Records'!L401 -> 0
A34: ='01 Synthetic Records'!A403 -> SYN-0402 | B34: ='01 Synthetic Records'!F403 -> Missing page | C34: ='01 Synthetic Records'!B403 -> 6 | D34: ='01 Synthetic Records'!C403 -> 5 | E34: ='01 Synthetic Records'!G403 -> 1 | F34: ='01 Synthetic Records'!H403 -> 1 | G34: ='01 Synthetic Records'!I403 -> 0 | H34: ='01 Synthetic Records'!J403 -> 0 | I34: ='01 Synthetic Records'!K403 -> 0 | J34: ='01 Synthetic Records'!L403 -> 0
A35: ='01 Synthetic Records'!A431 -> SYN-0430 | B35: ='01 Synthetic Records'!F431 -> Content missing / wrong page | C35: ='01 Synthetic Records'!B431 -> 4 | D35: ='01 Synthetic Records'!C431 -> 4 | E35: ='01 Synthetic Records'!G431 -> 1 | F35: ='01 Synthetic Records'!H431 -> 1 | G35: ='01 Synthetic Records'!I431 -> 0 | H35: ='01 Synthetic Records'!J431 -> 0 | I35: ='01 Synthetic Records'!K431 -> 0 | J35: ='01 Synthetic Records'!L431 -> 0
A36: ='01 Synthetic Records'!A438 -> SYN-0437 | B36: ='01 Synthetic Records'!F438 -> Missing page | C36: ='01 Synthetic Records'!B438 -> 6 | D36: ='01 Synthetic Records'!C438 -> 5 | E36: ='01 Synthetic Records'!G438 -> 1 | F36: ='01 Synthetic Records'!H438 -> 1 | G36: ='01 Synthetic Records'!I438 -> 0 | H36: ='01 Synthetic Records'!J438 -> 0 | I36: ='01 Synthetic Records'!K438 -> 0 | J36: ='01 Synthetic Records'!L438 -> 0
A37: ='01 Synthetic Records'!A445 -> SYN-0444 | B37: ='01 Synthetic Records'!F445 -> Missing page | C37: ='01 Synthetic Records'!B445 -> 8 | D37: ='01 Synthetic Records'!C445 -> 7 | E37: ='01 Synthetic Records'!G445 -> 0 | F37: ='01 Synthetic Records'!H445 -> 0 | G37: ='01 Synthetic Records'!I445 -> 1 | H37: ='01 Synthetic Records'!J445 -> 1 | I37: ='01 Synthetic Records'!K445 -> 20 | J37: ='01 Synthetic Records'!L445 -> 20
A38: ='01 Synthetic Records'!A460 -> SYN-0459 | B38: ='01 Synthetic Records'!F460 -> Missing page | C38: ='01 Synthetic Records'!B460 -> 8 | D38: ='01 Synthetic Records'!C460 -> 7 | E38: ='01 Synthetic Records'!G460 -> 0 | F38: ='01 Synthetic Records'!H460 -> 1 | G38: ='01 Synthetic Records'!I460 -> 1 | H38: ='01 Synthetic Records'!J460 -> 0 | I38: ='01 Synthetic Records'!K460 -> 20 | J38: ='01 Synthetic Records'!L460 -> 0
A39: ='01 Synthetic Records'!A463 -> SYN-0462 | B39: ='01 Synthetic Records'!F463 -> Missing page | C39: ='01 Synthetic Records'!B463 -> 6 | D39: ='01 Synthetic Records'!C463 -> 5 | E39: ='01 Synthetic Records'!G463 -> 1 | F39: ='01 Synthetic Records'!H463 -> 1 | G39: ='01 Synthetic Records'!I463 -> 0 | H39: ='01 Synthetic Records'!J463 -> 0 | I39: ='01 Synthetic Records'!K463 -> 0 | J39: ='01 Synthetic Records'!L463 -> 0
A40: ='01 Synthetic Records'!A469 -> SYN-0468 | B40: ='01 Synthetic Records'!F469 -> Missing page | C40: ='01 Synthetic Records'!B469 -> 7 | D40: ='01 Synthetic Records'!C469 -> 6 | E40: ='01 Synthetic Records'!G469 -> 1 | F40: ='01 Synthetic Records'!H469 -> 1 | G40: ='01 Synthetic Records'!I469 -> 0 | H40: ='01 Synthetic Records'!J469 -> 0 | I40: ='01 Synthetic Records'!K469 -> 0 | J40: ='01 Synthetic Records'!L469 -> 0
...

Sheet 04 Workflow Controls
A1: Control ID | B1: Stage | C1: Verification / decision | D1: Fail / exception pathway | E1: Audit evidence
A2: C01 | B2: Receipt | C2: Confirm verified expected count from source manifest | D2: Hold; request authoritative count | E2: Source ID, timestamp
A3: C02 | B3: Capture | C3: Compare actual pages to verified expected count | D3: Hold; rescan / request missing pages | E3: Page counts and result
A4: C03 | B4: Content | C4: Check page sequence, identity, legibility and required content | D4: Hold for human review; page match alone insufficient | E4: Reviewer and finding
A5: C04 | B5: Indexing | C5: Only release when all checks pass | D5: Prevent completion; assign owner | E5: Release decision
A6: C05 | B6: Resolution | C6: Correct document and repeat checks | D6: Escalate unresolved exception | E6: Action, owner, resolution time

Sheet 05 Methodology
A1: MODEL / DATA DICTIONARY | B1: Value | C1: Interpretation
A2: Project classification | B2: Student-developed; simulated; educational; no PHI | C2: Not a real EHR export
A3: Observation unit | B3: One synthetic document | C3: 500 identical IDs across both scenarios
A4: Counterfactual | B4: Same underlying defects | C4: Only detection outcome changes
A5: Ground truth | B5: Defect Type / Ground Truth Complete | C5: Not inferred solely from page-count match
A6: Expected-page evidence | B6: Synthetic manifest + checklist | C6: Assumed verified source
A7: Rework minutes per escaped defect | B7: 20 | C7: Illustrative assumption; excludes checkpoint costs
A8: Detection allocation | B8: 25 baseline / 38 proposed | C8: Proposed group includes all baseline detections
A9: Defect escape | B9: Incomplete AND not detected | C9: Escaped count, not necessarily clinical harm
A10: Detection rate | B10: Detected / incomplete | C10: Denominator is 40 defects
A11: Escape rate | B11: Escaped / incomplete | C11: Complement of detection
A12: Rework hours | B12: Escaped * 20 / 60 | C12: Downstream only, not net savings
A13: First-pass completeness | B13: Complete / all documents | C13: Not equal to detection rate
A14: Limitations | B14: No patient, payer, clinical or facility records | C14: No validated intervention effect
A15: Reference | B15: AHIMA Document Management and Imaging Toolkit | C15: https://www.ahima.org/media/4y1buocf/document-management-and-imaging-toolkit_axs.pdf
A16: Created by | B16: Kori Pickle | BSHA Candidate | C16: Healthcare Operations Intelligence Engine™
